//  GTCEu Modern 多方块机器定义脚本
//  适用于 KubeJS GTCEuStartupEvents
//  包含：
//    1. 原木处理机 (wooden_processor)
//    2. AE压印器 (ae_processor_multiblock)
// ============================================================

// 导入 GTCEu 多方块结构构建所需的类
const FactoryBlockPattern = Java.loadClass('com.gregtechceu.gtceu.api.pattern.FactoryBlockPattern');
const Predicates = Java.loadClass('com.gregtechceu.gtceu.api.pattern.Predicates');

// ============================================
// 多方块名称：原木处理机
// ============================================

// --- 注册一种新的配方类型：wood ---
GTCEuStartupEvents.registry('gtceu:recipe_type', event => {
    event.create('wood')
        .category('wood')               // 在 JEI 中的分类标签
        .setEUIO('in')                  // 能量输入类型（in = 消耗能量）
        .setMaxIOSize(1, 1, 0, 0)       // 最多 1 个物品输入、1 个物品输出、0 流体输入、0 流体输出
        .setSlotOverlay(false, false, GuiTextures.SOLIDIFIER_OVERLAY) // 用固化器槽位覆盖层
        .setProgressBar(GuiTextures.PROGRESS_BAR_ARROW, FillDirection.LEFT_TO_RIGHT) // 进度条样式：箭头，从左到右
})

// --- 注册多方块机器：原木处理机 ---
GTCEuStartupEvents.registry('gtceu:machine', event => {
    event.create('wooden_processor', 'multiblock')
        .rotationState(RotationState.NON_Y_AXIS)    // 可以面向任何非 Y 轴的方向（水平方向可旋转）
        .recipeType('wood')                         // 绑定到上面定义的 'wood' 配方类型
        .recipeModifiers(GTRecipeModifiers.ELECTRIC_OVERCLOCK.apply(OverclockingLogic.NON_PERFECT_OVERCLOCK)) // 支持电力超频，但采用非完美超频逻辑

        // --- 多方块结构定义 ---
        .pattern(definition => FactoryBlockPattern.start()
            // 每个 .aisle() 定义一**层**（Y 方向）；每个字符串代表该层在 Z 方向的一排方块。
            // 整个结构共有 15 个 aisle（即 15 层高），每层有 24 列（对应 X 方向的 24 个位置）。
            // 这里用 24 个字符串描述一层的所有 Z 轴向切片 (X 方向从左到右，每个字符串长度为 15，对应 Z 方向的前后)。
            .aisle("XXXXXXXXXXXXXXX", "XXXXXXXXXXXXXXX", "XXXXXXXXXXXXXXX", "               ", "               ", "               ", "               ", "               ", "               ", "               ", "               ", "               ", "BBBBBBBBBBBBBBB", "BBBBBBBBBBBBBBB", "BBBBBBBBBBBBBBB", "      BBB      ", "      BBB      ", "      BBB      ", "               ", "               ", "               ", "               ", "               ", "               ",)
            .aisle("XXXXXXXXXXXXXXX", "XXXXXXXXXXXXXXX", "XXXXXXXXXXXXXXX", "               ", "               ", "               ", "               ", "               ", "               ", "               ", "               ", "               ", "BBBBBBBBBBBBBBB", "BBBBBBBBBBBBBBB", "BBBBBBBBBBBBBBB", "      BBB      ", "      BBB      ", "      BBB      ", "               ", "               ", "               ", "               ", "               ", "               ",)
            .aisle("XXXXXXXXXXXXXXX", "XXXXXXXXXXXXXXX", "XXXXXXXXXXXXXXX", "               ", "               ", "               ", "               ", "               ", "               ", "               ", "               ", "               ", "BBBBBBBBBBBBBBB", "BBBBBBBBBBBBBBB", "BBBBBBBBBBBBBBB", "      BBB      ", "      BBB      ", "      BBB      ", "               ", "               ", "               ", "               ", "               ", "               ",)
            .aisle("XXXXXXXXXXXXXXX", "XXXXXXXXXXXXXXX", "XXXXXXXXXXXXXXX", "               ", "               ", "               ", "               ", "               ", "               ", "               ", "               ", "               ", "BBBBBBBBBBBBBBB", "BBBBBBBBBBBBBBB", "BBBBBBBBBBBBBBB", "   BBBBBBBBB   ", "   BBBBBBBBB   ", "   BBBBBBBBB   ", "      BBB      ", "      BBB      ", "      BBB      ", "               ", "               ", "               ",)
            .aisle("XXXXXXXXXXXXXXX", "XXXXXXXXXXXXXXX", "XXXXXXXXXXXXXXX", "               ", "               ", "               ", "               ", "               ", "               ", "               ", "               ", "               ", "BBBBBBBBBBBBBBB", "BBBBBBBBBBBBBBB", "BBBBBBBBBBBBBBB", "   BBBBBBBBB   ", "   BBBBBBBBB   ", "   BBBBBBBBB   ", "      BBB      ", "      BBB      ", "      BBB      ", "               ", "               ", "               ",)
            .aisle("XXXXXXXXXXXXXXX", "XXXXXXXXXXXXXXX", "XXXXXXXXXXXXXXX", "               ", "               ", "               ", "               ", "               ", "               ", "               ", "               ", "               ", "BBBBBBBBBBBBBBB", "BBBBBBBBBBBBBBB", "BBBBBBBBBBBBBBB", "   BBBBBBBBB   ", "   BBBBBBBBB   ", "   BBBBBBBBB   ", "      BBB      ", "      BBB      ", "      BBB      ", "               ", "               ", "               ",)
            .aisle("XXXXXXXXXXXXXXX", "XXXXXXXXXXXXXXX", "XXXXXXXXXXXXXXX", "      AAA      ", "      AAA      ", "      AAA      ", "      AAA      ", "      AAA      ", "      AAA      ", "      AAA      ", "      AAA      ", "      AAA      ", "BBBBBBAAABBBBBB", "BBBBBBAAABBBBBB", "BBBBBBAAABBBBBB", "BBBBBBAAABBBBBB", "BBBBBBAAABBBBBB", "BBBBBBAAABBBBBB", "   BBBAAABBB   ", "   BBBAAABBB   ", "   BBBAAABBB   ", "      BBB      ", "      BBB      ", "      BBB      ",)
            .aisle("XXXXXXXXXXXXXXX", "XXXXXXXXXXXXXXX", "XXXXXXXXXXXXXXX", "      AAA      ", "      AAA      ", "      AAA      ", "      AAA      ", "      AAA      ", "      AAA      ", "      AAA      ", "      AAA      ", "      AAA      ", "BBBBBBAAABBBBBB", "BBBBBBAAABBBBBB", "BBBBBBAAABBBBBB", "BBBBBBAAABBBBBB", "BBBBBBAAABBBBBB", "BBBBBBAAABBBBBB", "   BBBAAABBB   ", "   BBBAAABBB   ", "   BBBAAABBB   ", "      BBB      ", "      BBB      ", "      BBB      ",)
            .aisle("XXXXXXXXXXXXXXX", "XXXXXXXXXXXXXXX", "XXXXXXXXXXXXXXX", "      AAA      ", "      AMA      ", "      AAA      ", "      AAA      ", "      AAA      ", "      AAA      ", "      AAA      ", "      AAA      ", "      AAA      ", "BBBBBBAAABBBBBB", "BBBBBBAAABBBBBB", "BBBBBBAAABBBBBB", "BBBBBBAAABBBBBB", "BBBBBBAAABBBBBB", "BBBBBBAAABBBBBB", "   BBBAAABBB   ", "   BBBAAABBB   ", "   BBBAAABBB   ", "      BBB      ", "      BBB      ", "      BBB      ",)
            // 注意：第 9 层中间有 'M' 符号，代表控制器位置（但在实际字符串中用的是 'M'？）
            // 这里原代码最初用的是 'M' 符号，后来似乎改用了 'A'。当前文件内容显示为 "A" 和 "M" 混用。
            // 但下面 where 中定义了 'M' 为控制器，同时 'A' 也允许 autoAbilities。
            // 为保持一致，此处保留原始结构，不做修改。
            .aisle("XXXXXXXXXXXXXXX", "XXXXXXXXXXXXXXX", "XXXXXXXXXXXXXXX", "               ", "               ", "               ", "               ", "               ", "               ", "               ", "               ", "               ", "BBBBBBBBBBBBBBB", "BBBBBBBBBBBBBBB", "BBBBBBBBBBBBBBB", "   BBBBBBBBB   ", "   BBBBBBBBB   ", "   BBBBBBBBB   ", "      BBB      ", "      BBB      ", "      BBB      ", "               ", "               ", "               ",)
            .aisle("XXXXXXXXXXXXXXX", "XXXXXXXXXXXXXXX", "XXXXXXXXXXXXXXX", "               ", "               ", "               ", "               ", "               ", "               ", "               ", "               ", "               ", "BBBBBBBBBBBBBBB", "BBBBBBBBBBBBBBB", "BBBBBBBBBBBBBBB", "   BBBBBBBBB   ", "   BBBBBBBBB   ", "   BBBBBBBBB   ", "      BBB      ", "      BBB      ", "      BBB      ", "               ", "               ", "               ",)
            .aisle("XXXXXXXXXXXXXXX", "XXXXXXXXXXXXXXX", "XXXXXXXXXXXXXXX", "               ", "               ", "               ", "               ", "               ", "               ", "               ", "               ", "               ", "BBBBBBBBBBBBBBB", "BBBBBBBBBBBBBBB", "BBBBBBBBBBBBBBB", "   BBBBBBBBB   ", "   BBBBBBBBB   ", "   BBBBBBBBB   ", "      BBB      ", "      BBB      ", "      BBB      ", "               ", "               ", "               ",)
            .aisle("XXXXXXXXXXXXXXX", "XXXXXXXXXXXXXXX", "XXXXXXXXXXXXXXX", "               ", "               ", "               ", "               ", "               ", "               ", "               ", "               ", "               ", "BBBBBBBBBBBBBBB", "BBBBBBBBBBBBBBB", "BBBBBBBBBBBBBBB", "      BBB      ", "      BBB      ", "      BBB      ", "               ", "               ", "               ", "               ", "               ", "               ",)
            .aisle("XXXXXXXXXXXXXXX", "XXXXXXXXXXXXXXX", "XXXXXXXXXXXXXXX", "               ", "               ", "               ", "               ", "               ", "               ", "               ", "               ", "               ", "BBBBBBBBBBBBBBB", "BBBBBBBBBBBBBBB", "BBBBBBBBBBBBBBB", "      BBB      ", "      BBB      ", "      BBB      ", "               ", "               ", "               ", "               ", "               ", "               ",)
            .aisle("XXXXXXXXXXXXXXX", "XXXXXXXXXXXXXXX", "XXXXXXXXXXXXXXX", "               ", "               ", "               ", "               ", "               ", "               ", "               ", "               ", "               ", "BBBBBBBBBBBBBBB", "BBBBBBBBBBBBBBB", "BBBBBBBBBBBBBBB", "      BBB      ", "      BBB      ", "      BBB      ", "               ", "               ", "               ", "               ", "               ", "               ",)

            // 定义结构中的字符对应的方块或条件
            .where('M', Predicates.controller(Predicates.blocks(definition.get()))) // 控制器，必须为本机器方块
            .where('A', Predicates.blocks('kubejs:wooden_casing')                 // 木质外壳
                .or(Predicates.autoAbilities(definition.getRecipeTypes())))      // 或由系统自动赋予输入/输出/能量/维护等能力
            .where(' ', Predicates.any())                                         // 空格代表任何方块（通常为空气）
            .where('X', Predicates.blocks('kubejs:dirt_casing'))                  // 泥土外壳
            .where('B', Predicates.blocks('kubejs:leaves_casing'))                // 树叶外壳
            .build()                                                             // 完成结构构建
        )

        // 工作时显示的外壳模型（使用橡木原木的方块模型）
        .workableCasingModel(
            "minecraft:block/oak_log",
            "minecraft:block/oak_log"
        )
})

// ============================================
// 多方块名称：AE压印器
// ============================================

// --- 注册配方类型：ae_processor ---
GTCEuStartupEvents.registry('gtceu:recipe_type', event => {
    event.create('ae_processor')
        .category('ae_processor')
        .setEUIO('in')
        .setMaxIOSize(3, 1, 0, 0) // 3 个物品输入，1 个物品输出，无流体
        .setSlotOverlay(false, false, GuiTextures.SOLIDIFIER_OVERLAY)
        .setProgressBar(GuiTextures.PROGRESS_BAR_ARROW, FillDirection.LEFT_TO_RIGHT)
})

// --- 注册多方块机器：AE压印器 ---
GTCEuStartupEvents.registry('gtceu:machine', event => {
    event.create('ae_processor_multiblock', 'multiblock') // 机器 ID 为 ae_processor_multiblock
        .rotationState(RotationState.NON_Y_AXIS)
        .recipeType('ae_processor')                      // 使用上面定义的配方类型
        .recipeModifiers(GTRecipeModifiers.ELECTRIC_OVERCLOCK.apply(OverclockingLogic.NON_PERFECT_OVERCLOCK))
        
        // --- 结构定义（3x3x3 小型多方块） ---
        .pattern(definition => FactoryBlockPattern.start()
            // 底层（第 1 层）
            .aisle("BBB", "XXX", "XXX")
            // 中层（第 2 层），包含控制器
            .aisle("BBB", "A X", "XXX")
            // 顶层（第 3 层）
            .aisle("BBB", "XXX", "XXX")
            
            // 字符对应方块/条件
            .where('A', Predicates.controller(Predicates.blocks(definition.get()))) // 控制器（必须正好 1 个）
            .where('X', Predicates.blocks('ae2:quartz_block'))
            // B 可以是 AE2 福鲁伊克斯块，或自动提供输入/输出/能源/维护的能力方块
            .where('B', Predicates.blocks('ae2:fluix_block')
            .or(Predicates.autoAbilities(definition.getRecipeTypes())))
            .build()
        )
        
        // 工作模型：使用 AE2 石英玻璃的材质
        .workableCasingModel(
            "ae2:block/fluix_block",
            "ae2:block/fluix_block"
        )
        
})

// --- 注册配方类型：大型高炉 ---
GTCEuStartupEvents.registry('gtceu:recipe_type', event => {
    event.create('bigger_blast_furnace')
        .category('bigger_blast_furnace')
        .setMaxIOSize(2, 2, 0, 0) // 2 个物品输入，2 个物品输出，无流体
        .setSlotOverlay(false, false, GuiTextures.SOLIDIFIER_OVERLAY)
        .setProgressBar(GuiTextures.PROGRESS_BAR_ARROW, FillDirection.LEFT_TO_RIGHT)
})


        // ============================================
// --- 注册配方类型：processor ---
GTCEuStartupEvents.registry('gtceu:recipe_type', event => {
    event.create('processor')
        .category('processor')
        .setEUIO('in')
        .setMaxIOSize(3, 1, 0, 0) // 3 个物品输入，1 个物品输出，无流体
        .setSlotOverlay(false, false, GuiTextures.SOLIDIFIER_OVERLAY)
        .setProgressBar(GuiTextures.PROGRESS_BAR_ARROW, FillDirection.LEFT_TO_RIGHT)
})

// --- 注册多方块机器：锻造处理机 ---
GTCEuStartupEvents.registry('gtceu:machine', event => {
    event.create('bigger_smithing_table', 'multiblock') // 机器 ID 为 bigger_blast_furnace_multiblock
        .rotationState(RotationState.NON_Y_AXIS)
        .recipeType('processor')                      // 使用上面定义的配方类型
        .recipeModifiers(GTRecipeModifiers.ELECTRIC_OVERCLOCK.apply(OverclockingLogic.NON_PERFECT_OVERCLOCK))
        
        // --- 结构定义（16x16x16 大型多方块） ---
        .pattern(definition => FactoryBlockPattern.start()
            .aisle("XXXXXXXXXXXXXXXX","XXBBBBBBBBBBBBXX","XXBBBBBBBBBBBBXX","XXBBBBBBBBTBBBXX","XXBBBBBBBBTBBBXX","XXBBBBBBBBTBBBXX","XXBBBBBBBBTBBBXX","XXBBBBBBRRRRRBXX","XXBBBBBBRRRRRBXX","XXBBBBBBRRRRRBXX","XXBBBBBBBBTBBBXX","XXBBBBBBBBBBBBXX","XXXXXXXXXXXXXXXX","XXXXXXXXXXXXXXXX","XXXXXXXXXXXXXXXX","XXXXXXXXXXXXXXXX")
            .aisle("XXXXXXXXXXXXXXXX","X              X","X              X","X              X","X              X","X              X","X              X","X              X","X              X","X              X","X              X","X              X","X              X","X              X","X              X","XXXXXXXXXXXXXXXX")
            .aisle("XXXXXXXXXXXXXXXX","B              B","B              B","B              B","B              B","B              B","B              B","B              B","B              B","B              B","B              B","B              B","X              X","X              X","X              X","XXXXXXXXXXXXXXXX")
            .aisle("XXXXXXXXXXXXXXXX","B              B","B              B","B              B","T              B","T              B","T              B","R              R","R              R","R              R","B              B","B              B","X              X","X              X","X              X","XXXXXXXXXXXXXXXX")
            .aisle("XXXXXXXXXXXXXXXX","B              B","B              B","B              B","B              B","B              R","B              R","B              B","B              B","B              R","B              B","B              B","X              X","X              X","X              X","XXXXXXXXXXXXXXXX")
            .aisle("XXXXXXXXXXXXXXXX","B              B","B              B","B              R","Y              R","T              B","T              B","T              B","R              B","R              B","R              B","B              B","X              X","X              X","X              X","XXXXXXXXXXXXXXXX")
            .aisle("XXXXXXXXXXXXXXXX","B              B","B              B","B              B","B              B","B              R","B              R","B              B","B              B","B              R","B              B","B              B","X              X","X              X","X              X","XXXXXXXXXXXXXXXX")
            .aisle("XXXXXXXXXXXXXXXX","B              B","B              B","B              B","B              B","B              B","B              B","B              R","B              R","B              R","B              B","B              B","X              X","X              X","X              X","XXXXXXXXXXXXXXXX")
            .aisle("XXXXXXXXXXXXXXXX","B              B","B              B","B              B","B              B","B              B","B              B","R              B","R              B","R              B","B              B","B              B","X              X","X              X","X              X","XXXXXXXXXXXXXXXX")
            .aisle("XXXXXXXXXXXXXXXX","B              B","B              B","B              B","B              B","R              B","R              B","B              B","B              B","R              B","B              B","B              B","X              X","X              X","X              X","XXXXXXXXXXXXXXXX")
            .aisle("XXXXXXXXXXXXXXXX","B              B","B              B","R              B","R              Y","B              T","B              T","B              T","B              R","B              R","B              R","B              B","X              X","X              X","X              X","XXXXXXXXXXXXXXXX")
            .aisle("XXXXXXXXXXXXXXXX","B              B","B              B","B              B","B              B","R              B","R              B","B              B","B              B","R              B","B              B","B              B","X              X","X              X","X              X","XXXXXXXXXXXXXXXX")
            .aisle("XXXXXXXXXXXXXXXX","B              B","B              B","B              B","B              T","B              T","B              T","R              R","R              R","R              R","B              B","B              B","X              X","X              X","X              X","XXXXXXXXXXXXXXXX")
            .aisle("XXXXXXXXXXXXXXXX","B              B","B              B","B              B","B              B","B              B","B              B","B              B","B              B","B              B","B              B","B              B","X              X","X              X","X              X","XXXXXXXXXXXXXXXX")
            .aisle("XXXXXXXXXXXXXXXX","X              X","X              X","X              X","X              X","X              X","X              X","X              X","X              X","X              X","X              X","X              X","X              X","X              X","X              X","XXXXXXXXXXXXXXXX")
            .aisle("XXXXXXXXXXXXXXXX","XXBBBBBBBBBBBAXX","XXBBBBBBBBBBBBXX","XXBBBTBBBBBBBBXX","XXBBBTBBBBBBBBXX","XXBBBTBBBBBBBBXX","XXBBBTBBBBBBBBXX","XXBRRRRRBBBBBBXX","XXBRRRRRBBBBBBXX","XXBRRRRRBBBBBBXX","XXBBBTBBBBBBBBXX","XXBBBBBBBBBBBBXX","XXXXXXXXXXXXXXXX","XXXXXXXXXXXXXXXX","XXXXXXXXXXXXXXXX","XXXXXXXXXXXXXXXX")
            // 字符对应方块/条件
            .where('A', Predicates.controller(Predicates.blocks(definition.get()))) // 控制器（必须正好 1 个）
            .where('X', Predicates.blocks('minecraft:black_concrete'))
            .where('Y', Predicates.blocks('minecraft:light_gray_concrete'))
            .where('R', Predicates.blocks('minecraft:gray_concrete'))
            .where('T', Predicates.blocks('minecraft:brown_concrete'))
            .where(' ', Predicates.any())
            // B 可以是 红色混凝土，或自动提供输入/输出/能源/维护的能力方块
            .where('B', Predicates.blocks('minecraft:red_concrete')
            .or(Predicates.autoAbilities(definition.getRecipeTypes())))
            .build()
        )
        
        // 工作模型：使用红色混凝土的材质
        .workableCasingModel(
            "minecraft:block/red_concrete",
            "minecraft:block/red_concrete"
        )
})


GTCEuStartupEvents.registry('gtceu:machine', event => {
    event.create('bigger_furnace', 'multiblock')
        .rotationState(RotationState.NON_Y_AXIS)
        .recipeType('electric_furnace')
        .recipeModifiers(GTRecipeModifiers.ELECTRIC_OVERCLOCK.apply(OverclockingLogic.NON_PERFECT_OVERCLOCK))
        .pattern(definition => FactoryBlockPattern.start()
.aisle("              ", "              ", "              ", "              ", "              ", "              ", "              ", "              ", "              ", "              ", "      AA      ", "              ", "              ", "              ", "              ", "              ", "              ", "              ", "              ", "              ", "              ", "              ", "              ", "              ")
.aisle("              ", "              ", "              ", "              ", "              ", "              ", "              ", "              ", "              ", "              ", "      AA      ", "              ", "              ", "              ", "              ", "              ", "              ", "              ", "              ", "              ", "              ", "              ", "              ", "              ")
.aisle("              ", "              ", "              ", "              ", "              ", "              ", "              ", "              ", "              ", "      AA      ", "              ", "              ", "              ", "              ", "              ", "              ", "              ", "              ", "              ", "              ", "              ", "              ", "              ", "              ")
.aisle("              ", "              ", "              ", "              ", "              ", "              ", "              ", "              ", "      AA      ", "      AA      ", "              ", "              ", "              ", "              ", "              ", "              ", "              ", "              ", "              ", "              ", "              ", "              ", "              ", "              ")
.aisle("  BB      BB  ", "    BBBBBB    ", "              ", "      BB      ", "      BB      ", "    BBBBBB    ", "    BB  BB    ", "    BB  BB    ", "    BBBBBB    ", "      BB      ", "      BB      ", "              ", "              ", "              ", "              ", "              ", "    CC  CC    ", "              ", "              ", "              ", "              ", "              ", "              ", "              ")
.aisle("  BB      BB  ", "  BBBBBBBBBB  ", "              ", "      BB      ", "      BB      ", "    BBBBBB    ", "    BB  BB    ", "    BB  BB    ", "    BBBBBB    ", "    BBBBBB    ", "      BB      ", "      BB      ", "              ", "              ", "              ", "              ", "    CC  CC    ", "              ", "              ", "              ", "              ", "              ", "              ", "              ")
.aisle("BBDDDDDDDDDDBB", " BDDDDDDDDDDB ", "    BBBBBB    ", "    BBBBBB    ", "  EEFFFFFFEE  ", "  EEFFFFFFEE  ", "              ", "              ", "  EE      EE  ", "  EE      EE  ", "  BBBBBBBBBB  ", "    BBBBBB    ", "      BB      ", "    GGBBGG    ", "    KL  KL    ", "    KL  KL    ", "  CCJJCCJJCC  ", "    CC  CC    ", "              ", "              ", "    CC  CC    ", "              ", "              ", "              ")
.aisle("BBDDDDDDDDDDBB", " BDDDDDDDDDDB ", "    BBBBBB    ", "    BBBBBB    ", "  EEFFFFFFEE  ", "  EEFFFFFFEE  ", "              ", "              ", "  EE      EE  ", "  EE      EE  ", "  BBBBBBBBBB  ", "    BBBBBB    ", "    GGBBGG    ", "    GGBBGG    ", "    HI  HI    ", "    HI  HI    ", "  CC22CC22CC  ", "    CC  CC    ", "              ", "              ", "    CC  CC    ", "              ", "              ", "              ")
.aisle("  DDDDDDDDDD  ", "BBDDDDDDDDDDBB", "  BB  [[  BB  ", "  BB      BB  ", "  FFFFFFFFFF  ", "BBFFFFFFFFFFBB", "BB          BB", "BB          BB", "BB          BB", " B          B ", "  BB      BB  ", "  BB      BB  ", "   G      G   ", "  GG      GG  ", "  KL      KL  ", "  KL      KL  ", "CCJO      PJCC", "  CCVXGGVXCC  ", "    YZ  YZ    ", "    YZ  YZ    ", "  CCUUCCUUCC  ", "    CC  CC    ", "              ", "              ")
.aisle("  DDDDDDDDDD  ", "BBDDDDDDDDDDBB", "  BB  [[  BB  ", "  BB      BB  ", "  FFFFFFFFFF  ", "BBFFFFFFFFFFBB", "BB          BB", "BB          BB", "BB          BB", " B          B ", "  BB      BB  ", "  BB      BB  ", "   G      G   ", "  GG      GG  ", "  HI      HI  ", "  HI      HI  ", "CCJO      PJCC", "  CCQWGGWRCC  ", "    SRGGQT    ", "    ST  ST    ", "  CCUUCCUUCC  ", "    CC  CC    ", "              ", "              ")
.aisle("  DDDDDDDDDD  ", "BBDDDDDDDDDDBB", "  BB[[[[[[BB  ", "BBBB      BBBB", "BBFFFFFFFFFFBB", "BBFFFFFFFFFFBB", "              ", "              ", "BB          BB", "BB          BB", "BBBB      BBBB", " BBB      BBB ", "  BB      BB  ", "  BB      BB  ", "              ", "              ", "  CC      CC  ", "    GG  GG    ", "     G  G     ", "              ", "    CCCCCC    ", "      CC      ", "      CC      ", "      CC      ")
.aisle("  DDDDDDDDDD  ", "1BDDDDDDDDDDBB", "  BB[[[[[[BB  ", "BBBB      BBBB", "BBFFFFFFFFFFBB", "BBFFFFFFFFFFBB", "              ", "              ", "BB          BB", "BB          BB", "BBBB      BBBB", " BBB      BBB ", "  BB      BB  ", "  BB      BB  ", "              ", "              ", "  CC      CC  ", "    GG  GG    ", "     G  G     ", "              ", "    CCCCCC    ", "      CC      ", "      CC      ", "      CC      ")
.aisle("  DDDDDDDDDD  ", "BBDDDDDDDDDDBB", "  BB  [[  BB  ", "  BB      BB  ", "  FFFFFFFFFF  ", "BBFFFFFFFFFFBB", "BB          BB", "BB          BB", "BB          BB", " B          B ", "  BB      BB  ", "  BB      BB  ", "   G      G   ", "  GG      GG  ", "  KL      KL  ", "  KL      KL  ", "CCJO      PJCC", "  CCVWGGWXCC  ", "    YXGGVZ    ", "    YZ  YZ    ", "  CCUUCCUUCC  ", "    CC  CC    ", "              ", "              ")
.aisle("  DDDDDDDDDD  ", "BBDDDDDDDDDDBB", "  BB  [[  BB  ", "  BB      BB  ", "  FFFFFFFFFF  ", "BBFFFFFFFFFFBB", "BB          BB", "BB          BB", "BB          BB", " B          B ", "  BB      BB  ", "  BB      BB  ", "   G      G   ", "  GG      GG  ", "  HI      HI  ", "  HI      HI  ", "CCJO      PJCC", "  CCQRGGQRCC  ", "    ST  ST    ", "    ST  ST    ", "  CCUUCCUUCC  ", "    CC  CC    ", "              ", "              ")
.aisle("BBDDDDDDDDDDBB", " BDDDDDDDDDDB ", "    BBBBBB    ", "    BBBBBB    ", "  EEFFFFFFEE  ", "  EEFFFFFFEE  ", "              ", "              ", "  EE      EE  ", "  EE      EE  ", "  BBBBBBBBBB  ", "    BBBBBB    ", "    GGBBGG    ", "    GGBBGG    ", "    KL  KL    ", "    KL  KL    ", "  CCMMCCMMCC  ", "    CC  CC    ", "              ", "              ", "    CC  CC    ", "              ", "              ", "              ")
.aisle("BBDDDDDDDDDDBB", " BDDDDDDDDDDB ", "    BBBBBB    ", "    BBBBBB    ", "  EEFFFFFFEE  ", "  EEFFFFFFEE  ", "              ", "              ", "  EE      EE  ", "  EE      EE  ", "  BBBBBBBBBB  ", "    BBBBBB    ", "      BB      ", "    GGBBGG    ", "    HI  HI    ", "    HI  HI    ", "  CCJJCCJJCC  ", "    CC  CC    ", "              ", "              ", "    CC  CC    ", "              ", "              ", "              ")
.aisle("  BB      BB  ", "  BBBBBBBBBB  ", "              ", "      BB      ", "      BB      ", "    BBBBBB    ", "    BB  BB    ", "    BB  BB    ", "    BBBBBB    ", "    BBBBBB    ", "      BB      ", "      BB      ", "              ", "              ", "              ", "              ", "    CC  CC    ", "              ", "              ", "              ", "              ", "              ", "              ", "              ")
.aisle("  BB      BB  ", "    BBBBBB    ", "              ", "      BB      ", "      BB      ", "    BBBBBB    ", "    BB  BB    ", "    BB  BB    ", "    BBBBBB    ", "      BB      ", "      BB      ", "              ", "              ", "              ", "              ", "              ", "    CC  CC    ", "              ", "              ", "              ", "              ", "              ", "              ", "              ")
.aisle("              ", "              ", "              ", "              ", "              ", "              ", "              ", "              ", "      AA      ", "      AA      ", "              ", "              ", "              ", "              ", "              ", "              ", "              ", "              ", "              ", "              ", "              ", "              ", "              ", "              ")
.aisle("              ", "              ", "              ", "              ", "              ", "              ", "              ", "              ", "              ", "      AA      ", "              ", "              ", "              ", "              ", "              ", "              ", "              ", "              ", "              ", "              ", "              ", "              ", "              ", "              ")
.aisle("              ", "              ", "              ", "              ", "              ", "              ", "              ", "              ", "              ", "              ", "      AA      ", "              ", "              ", "              ", "              ", "              ", "              ", "              ", "              ", "              ", "              ", "              ", "              ", "              ")
.aisle("              ", "              ", "              ", "              ", "              ", "              ", "              ", "              ", "              ", "              ", "      AA      ", "              ", "              ", "              ", "              ", "              ", "              ", "              ", "              ", "              ", "              ", "              ", "              ", "              ")
            .where('1', Predicates.controller(Predicates.blocks(definition.get())))
            .where('[', Predicates.blocks('minecraft:soul_campfire'))
            .where('D', Predicates.blocks('minecraft:smooth_stone'))
            .where('E', Predicates.blocks('minecraft:lodestone'))
            .where('C', Predicates.blocks('minecraft:deepslate_bricks'))
            .where('A', Predicates.blocks('minecraft:polished_diorite'))
            .where('G', Predicates.blocks('minecraft:stone_bricks'))
            .where('Q', Predicates.blocks('minecraft:stone_brick_wall'))
            .where('Z', Predicates.blocks('minecraft:stone_brick_wall'))
            .where('X', Predicates.blocks('minecraft:stone_brick_wall'))
            .where('S', Predicates.blocks('minecraft:stone_brick_wall'))
            .where('T', Predicates.blocks('minecraft:stone_brick_wall'))
            .where('Y', Predicates.blocks('minecraft:stone_brick_wall'))
            .where('U', Predicates.blocks('minecraft:stone_brick_wall'))
            .where('R', Predicates.blocks('minecraft:stone_brick_wall'))
            .where('V', Predicates.blocks('minecraft:stone_brick_wall'))
            .where('W', Predicates.blocks('minecraft:stone_brick_wall'))
            .where('K', Predicates.blocks('minecraft:deepslate_brick_wall'))
            .where('L', Predicates.blocks('minecraft:deepslate_brick_wall'))
            .where('H', Predicates.blocks('minecraft:deepslate_brick_wall'))
            .where('I', Predicates.blocks('minecraft:deepslate_brick_wall'))
            .where('2', Predicates.blocks('minecraft:deepslate_brick_wall'))
            .where('M', Predicates.blocks('minecraft:deepslate_brick_wall'))
            .where('O', Predicates.blocks('minecraft:deepslate_brick_wall'))
            .where('J', Predicates.blocks('minecraft:deepslate_brick_wall'))
            .where('O', Predicates.blocks('minecraft:deepslate_brick_wall'))
            .where('P', Predicates.blocks('minecraft:deepslate_brick_wall'))
            .where('F', Predicates.blocks('minecraft:tuff'))
            .where(' ', Predicates.any())
            .where('B', Predicates.blocks('minecraft:polished_andesite')
                .or(Predicates.autoAbilities(definition.getRecipeTypes())))
            .build()
        )
        .workableCasingModel(
            "minecraft:block/polished_andesite",
            "minecraft:block/polished_andesite"
        )
})

GTCEuStartupEvents.registry('gtceu:recipe_type', event => {
    event.create('natures_offering')
        .category('multiblock')
        .setEUIO('in')
        .setMaxIOSize(1, 1, 0, 0)
        .setSlotOverlay(false, false, GuiTextures.SOLIDIFIER_OVERLAY)
        .setProgressBar(GuiTextures.PROGRESS_BAR_ARROW, FillDirection.LEFT_TO_RIGHT)
})

GTCEuStartupEvents.registry('gtceu:machine', event => {
     event.create('natures_offering', 'multiblock')
        .rotationState(RotationState.NON_Y_AXIS)
        .recipeType('natures_offering')
        .recipeModifiers(GTRecipeModifiers.ELECTRIC_OVERCLOCK.apply(OverclockingLogic.NON_PERFECT_OVERCLOCK))
        .pattern(definition => FactoryBlockPattern.start()
.aisle("AAAAAAAAAAAAAAAAAAAAAAAAAAAAA", "AAAAAAAAAAAAAAAAAAAAAAAAAAAAA", "AAAAAAAAAAAAAAAAAAAAAAAAAAAAA", "TUi                       XUi", "                             ", "                             ", "                             ", "                             ", "                             ", "                             ", "                             ", "                             ", "HHH                       HHH", "                             ", "                             ", "                             ", "                             ", "                             ", "                             ", "                             ")
.aisle("AAAAAAAAAAAAAAAAAAAAAAAAAAAAA", "AAAAAAAAAAAAAAAAAAAAAAAAAAAAA", "AAAAAAAAAAAAAAAAAAAAAAAAAAAAA", "IAJ     KKKKHHHHHKKKK     IAJ", " A                         A ", " A                         A ", " A                         A ", " A                         A ", " A                         A ", " A                         A ", " A                         A ", " A                         A ", "HHH                       HHH", "                             ", "                             ", "                             ", "                             ", "                             ", "                             ", "                             ")
.aisle("AAAAAAAAAAAAAAAAAAAAAAAAAAAAA", "AAAAAAAAAAA1PPPPP1AAAAAAAAAAA", "AAAAAAAAAAA1PPPPP1AAAAAAAAAAA", "ECD    KHHHWHHHHHWHHHK    BCD", "           W     W           ", "           H     H           ", "                             ", "                             ", "                             ", "                             ", "                             ", "                             ", "HHH                       HHH", "                             ", "                             ", "                             ", "                             ", "                             ", "                             ", "                             ")
.aisle("AAAAAAAAAAAAAAAAAAAAAAAAAAAAA", "AAAAAAAAPPPPPPPPPPOOPAAAAAAAA", "AAAAAAAAPPPPPPPPPPPPPAAAAAAAA", "     KKH    ZZZZZ    HKK     ", "                             ", "           A     A           ", "                             ", "                             ", "                             ", "                             ", "                             ", "                             ", "                             ", "                             ", "                             ", "                             ", "                             ", "                             ", "                             ", "                             ")
.aisle("AAAAAAAAAAAAAAAAAAAAAAAAAAAAA", "AAAAAAAPPPP1PPPPP1OOPPAAAAAAA", "AAAAAAAPPPP1PPPPP1PPPPAAAAAAA", "    KHH    W[[[[[W    HHK    ", "           WHHHHHW           ", "           W     W           ", "           H     H           ", "                             ", "                             ", "                             ", "                             ", "                             ", "                             ", "                             ", "                             ", "                             ", "                             ", "                             ", "                             ", "                             ")
.aisle("AAAAAAAAAAAAAAAAAAAAAAAAAAAAA", "AAAAAPPPPPPPPPPPPPOOOOOOAAAAA", "AAAAAPPPPPPPPPPPPPPPPPPPAAAAA", "   KH                   HK   ", "            ZZZZZ            ", "                             ", "           A     A           ", "                             ", "                             ", "                             ", "                             ", "                             ", "                             ", "                             ", "                             ", "                             ", "                             ", "                             ", "                             ", "                             ")
.aisle("AAAAAAAAAAAAAAAAAAAAAAAAAAAAA", "AAAAAPPPPPP1PPPPP1OOOOPPAAAAA", "AAAAAPPPPPP1PPPPP1PPPPPPAAAAA", "   KH      W     W      HK   ", "           W[[[[[W           ", "           WHHHHHW           ", "           W     W           ", "           H     H           ", "                             ", "                             ", "                             ", "                             ", "                             ", "                             ", "                             ", "                             ", "                             ", "                             ", "                             ", "                             ")
.aisle("AAAAAAAAAAAAAAAAAAAAAAAAAAAAA", "AAAAOPPPPPPPPPPPPPOOOOPPPAAAA", "AAAAPPPPPPPPPPPPPPPPPPPPPAAAA", "  KH                     HK  ", "                             ", "            ZZZZZ            ", "           A     A           ", "                             ", "                             ", "                             ", "                             ", "              ]              ", "              ^              ", "                             ", "                             ", "                             ", "                             ", "                             ", "                             ", "                             ")
.aisle("AAAAAAAAAAAAAAAAAAAAAAAAAAAAA", "AAAOOPPPPPPPAAAAAOOOOOPPPAAAA", "AAAPPPPPPPP1AAAAA1PPPPPPPPAAA", " KH        1AAAAA1        HK ", "            AAAAA            ", "            AAAAA            ", "           H     H           ", "                             ", "                             ", "            HHHHH            ", "                             ", "                             ", "                             ", "                             ", "                             ", "                             ", "                             ", "                             ", "                             ", "                             ")
.aisle("AAAAAAAAAAAAAAAAAAAAAAAAAAAAA", "AAAOOOOOOOAAAAAAAAAOOOPPPPAAA", "AAAPPPPPPPAAAAAAAAAPPPPPPPAAA", " KH       AAAAAAAAA       HK ", "          AAAAAAAAA          ", "          AAAAAAAAA          ", "           W     W           ", "           W     W           ", "          cW     Wc          ", "          HH     HH          ", "                             ", "         ]         ]         ", "         ^         ^         ", "                             ", "                             ", "                             ", "                             ", "                             ", "                             ", "                             ")
.aisle("AAAAAAAAAAAAAAAAAAAAAAAAAAAAA", "AAAOOOOOOAAAAAAAAAAAOOPPPPAAA", "AAAPPPPPPAAAAAAAAAAAPPPPPPAAA", " KH      AAAAAAAAAAA      HK ", "         AAAAAAAAAAA         ", "         AAAAAAAAAAA         ", "                             ", "                             ", "         c         c         ", "         H         H         ", "                             ", "                             ", "                             ", "                             ", "                             ", "                             ", "                             ", "                             ", "                             ", "                             ")
.aisle("AAAAAAAAAAAAAAAAAAAAAAAAAAAAA", "AA1P1P1OOAAAAAAAAAAAOO1P1P1AA", "AA1P1P1P1AAAAAAAAAAA1P1P1P1AA", " KW W W 1AAAAAAAAAAA1 W W WK ", "  W W W  AAAAAAAAAAA  W W W  ", "  HAW W  AAAAAAAAAAA  W WAH  ", "    HAWAHW         WHAWAH    ", "      H  W         W  H      ", "         W         W         ", "         H         H         ", "                             ", "                             ", "                             ", "                             ", "                             ", "                             ", "                             ", "                             ", "                             ", "                             ")
.aisle("AAAAAAAAAAAAAAAAAAAAAAAAAAAAA", "AAPPPPPOAAAAAAAAAAAAAOOOOOOAA", "AAPPPPPPAAAAAAAAAAAAAPPPPPPAA", " HHZ[   AAAAAAAAAAAAA   [ZHH ", "    HZ[ AAAAAAAAAAAAA [ZH    ", "      HZAAAAAAAAAAAAAZH      ", "                             ", "                             ", "                             ", "        H           H        ", "                             ", "                             ", "                             ", "              d              ", "              d              ", "                             ", "                             ", "                             ", "                             ", "                             ")
.aisle("AAAAAAAAAAAAAAAAAAAAAAAAAAAAA", "AAPPPPPOAAAAAAAAAAAAAOOOOOOAA", "AAPPPPPPAAAAAAAAAAAAAPPPPPPAA", " HHZ[   AAAAAAAAAAAAA   [ZHH ", "    HZ[ AAAAAeeeAAAAA [ZH    ", "      HZAAAAAAAAAAAAAZH      ", "             HHH             ", "                             ", "                             ", "        H           H        ", "                             ", "              d              ", "             ddd             ", "             ddd             ", "             ddd             ", "             ddd             ", "              d              ", "                             ", "                             ", "                             ")
.aisle("AAAAAAAAAAAAAAAAAAAAAAAAAAAAA", "AAPPPPPOAAAAAAAAAAAAAOOOOOOAA", "AAPPPPPPAAAAAAAAAAAAAPPPPPPAA", " HHZ[   AAAAAAAAAAAAA   [ZHH ", "    HZ[ AAAAAeeeAAAAA [ZH    ", "      HZAAAAAAgAAAAAAZH      ", "             HhH             ", "                             ", "                             ", "        H     d     H        ", "              d              ", "       ]     ddd     ]       ", "       ^     ddd     ^       ", "            ddddd            ", "            ddddd            ", "             ddd             ", "             ddd             ", "              d              ", "              d              ", "                             ")
.aisle("AAAAAAAAAAAAAAAAAAAAAAAAAAAAA", "AAPPPPPOAAAAAAAAAAAAAOOOOOOAA", "AAPPPPPPAAAAAAAAAAAAAPPPPPPAA", " HHZ[   AAAAAAAAAAAAA   [ZHH ", "    HZ[ AAAAAeeeAAAAA [ZH    ", "      HZAAAAAAAAAAAAAZH      ", "             HHH             ", "                             ", "                             ", "        H           H        ", "                             ", "              d              ", "             ddd             ", "             ddd             ", "             ddd             ", "             ddd             ", "              d              ", "                             ", "                             ", "                             ")
.aisle("AAAAAAAAAAAAAAAAAAAAAAAAAAAAA", "AAPPPPPOAAAAAAAAAAAAAOOOOOOAA", "AAPPPPPPAAAAAAAAAAAAAPPPPPPAA", " HHZ[   AAAAAAAAAAAAA   [ZHH ", "    HZ[ AAAAAAAAAAAAA [ZH    ", "      HZAAAAAAfAAAAAAZH      ", "                             ", "                             ", "                             ", "        H           H        ", "                             ", "                             ", "                             ", "              d              ", "              d              ", "                             ", "                             ", "                             ", "                             ", "                             ")
.aisle("AAAAAAAAAAAAAAAAAAAAAAAAAAAAA", "AA1P1P1OOAAAAAAAAAAAOO1P1P1AA", "AA1P1P1P1AAAAAAAAAAA1P1P1P1AA", " KW W W 1AAAAAAAAAAA1 W W WK ", "  W W W  AAAAAAAAAAA  W W W  ", "  HAW W  AAAAAAAAAAA  W WAH  ", "    HAWAHW         WHAWAH    ", "      H  W         W  H      ", "         W         W         ", "         H         H         ", "                             ", "                             ", "                             ", "                             ", "                             ", "                             ", "                             ", "                             ", "                             ", "                             ")
.aisle("AAAAAAAAAAAAAAAAAAAAAAAAAAAAA", "AAAPPPPOOAAAAAAAAAAAOOOOOOAAA", "AAAPPPPPPAAAAAAAAAAAPPPPPPAAA", " KH      AAAAAAAAAAA      HK ", "         AAAAAAAAAAA         ", "         AAAAAAAAAAA         ", "                             ", "                             ", "         c         c         ", "         H         H         ", "                             ", "                             ", "                             ", "                             ", "                             ", "                             ", "                             ", "                             ", "                             ", "                             ")
.aisle("AAAAAAAAAAAAAAAAAAAAAAAAAAAAA", "AAAOOOOOOOAAAAAAAAAOOOOOOOAAA", "AAAPPPPPPPAAAAAAAAAPPPPPPPAAA", " KH       AAAAAAAAA       HK ", "          AAAAAAAAA          ", "          AAAAAAAAA          ", "           W     W           ", "           W     W           ", "          cW     Wc          ", "          HH     HH          ", "                             ", "         ]         ]         ", "         ^         ^         ", "                             ", "                             ", "                             ", "                             ", "                             ", "                             ", "                             ")
.aisle("AAAAAAAAAAAAAAAAAAAAAAAAAAAAA", "AAAOOOOOOOOOAAAAAOOOOOOOOOAAA", "AAAPPPPPPPP1AAAAA1PPPPPPPPAAA", " KH        1AAAAA1        HK ", "            AAAAA            ", "            AAAAA            ", "           H     H           ", "                             ", "                             ", "            HHHHH            ", "                             ", "                             ", "                             ", "                             ", "                             ", "                             ", "                             ", "                             ", "                             ", "                             ")
.aisle("AAAAAAAAAAAAAAAAAAAAAAAAAAAAA", "AAAAOOOOOOOPOOOPPPPPOOOOOAAAA", "AAAAPPPPPPPPPPPPPPPPPPPPPAAAA", "  KH                     HK  ", "                             ", "            ZZZZZ            ", "           A     A           ", "                             ", "                             ", "                             ", "                             ", "              ]              ", "              ^              ", "                             ", "                             ", "                             ", "                             ", "                             ", "                             ", "                             ")
.aisle("AAAAAAAAAAAAAAAAAAAAAAAAAAAAA", "AAAAAOOOOOO1OOOPP1PPOOOOAAAAA", "AAAAAPPPPPP1PPPPP1PPPPPPAAAAA", "   KH      W     W      HK   ", "           W[[[[[W           ", "           WHHHHHW           ", "           W     W           ", "           H     H           ", "                             ", "                             ", "                             ", "                             ", "                             ", "                             ", "                             ", "                             ", "                             ", "                             ", "                             ", "                             ")
.aisle("AAAAAAAAAAAAAAAAAAAAAAAAAAAAA", "AAAAAOOOOOOPOOOPPPPPOOOOAAAAA", "AAAAAPPPPPPPPPPPPPPPPPPPAAAAA", "   KH                   HK   ", "            ZZZZZ            ", "                             ", "           A     A           ", "                             ", "                             ", "                             ", "                             ", "                             ", "                             ", "                             ", "                             ", "                             ", "                             ", "                             ", "                             ", "                             ")
.aisle("AAAAAAAAAAAAAAAAAAAAAAAAAAAAA", "AAAAAAAOOOO1OOOPP1PPOOAAAAAAA", "AAAAAAAPPPP1PPPPP1PPPPAAAAAAA", "    KHH    W[[[[[W    HHK    ", "           WHHHHHW           ", "           W     W           ", "           H     H           ", "                             ", "                             ", "                             ", "                             ", "                             ", "                             ", "                             ", "                             ", "                             ", "                             ", "                             ", "                             ", "                             ")
.aisle("AAAAAAAAAAAAAAAAAAAAAAAAAAAAA", "AAAAAAAAOOOPOOOPPPPPOAAAAAAAA", "AAAAAAAAPPPPPPPPPPPPPAAAAAAAA", "     KKH    ZZZZZ    HKK     ", "                             ", "           A     A           ", "                             ", "                             ", "                             ", "                             ", "                             ", "                             ", "                             ", "                             ", "                             ", "                             ", "                             ", "                             ", "                             ", "                             ")
.aisle("AAAAAAAAAAAAAAAAAAAAAAAAAAAAA", "AAAAAAAAAAA1OOOPP1AAAAAAAAAAA", "AAAAAAAAAAA1PPPPP1AAAAAAAAAAA", "TUV    KHHHWHHHHHWHHHK    XUV", "           W     W           ", "           H     H           ", "                             ", "                             ", "                             ", "                             ", "                             ", "                             ", "HHH                       HHH", "                             ", "                             ", "                             ", "                             ", "                             ", "                             ", "                             ")
.aisle("AAAAAAAAAAAAAAAAAAAAAAAAAAAAA", "AAAAAAAAAAAAAAAAAAAAAAAAAAAAA", "AAAAAAAAAAAAAAAAAAAAAAAAAAAAA", "IAJ     KKKKHHHHHKKKK     IAJ", " A                         A ", " A                         A ", " A                         A ", " A                         A ", " A                         A ", " A                         A ", " A                         A ", " A                         A ", "HHH                       HHH", "                             ", "                             ", "                             ", "                             ", "                             ", "                             ", "                             ")
.aisle("AAAAAAAAAAAAAAAAAAAAAAAAAAAAA", "AAAAAAAAAAAAAAAAAAAAAAAAAAAAA", "AAAAAAAAAAAAAAAAAAAAAAAAAAAAA", "BCD                       ECF", "                             ", "                             ", "                             ", "                             ", "                             ", "                             ", "                             ", "                             ", "HHH                       HHH", "                             ", "                             ", "                             ", "                             ", "                             ", "                             ", "                             ")
.where('A',Predicates.blocks('minecraft:smooth_quartz')
.or(Predicates.autoAbilities(definition.getRecipeTypes())))
.where('O', Predicates.fluids(Fluid.of('minecraft:water')))
.where('P', Predicates.fluids(Fluid.of('minecraft:water')))
.where('1',Predicates.blocks('minecraft:diorite_wall'))
.where('W',Predicates.blocks('minecraft:diorite_wall'))
.where('K',Predicates.blocks('minecraft:cherry_leaves'))
.where('d',Predicates.blocks('connectedglass:clear_glass_light_blue'))
.where('e',Predicates.blocks('minecraft:diamond_block'))
.where('c',Predicates.blocks('minecraft:soul_lantern'))
.where('g',Predicates.blocks('minecraft:beacon'))
.where('H', Predicates.blocks('minecraft:smooth_quartz_slab'))
.where('[', Predicates.blocks('minecraft:smooth_quartz_slab'))
.where('Z', Predicates.blocks('minecraft:smooth_quartz_slab'))
.where('C', Predicates.blocks('minecraft:smooth_quartz_stairs'))
.where('B', Predicates.blocks('minecraft:smooth_quartz_stairs'))
.where('D', Predicates.blocks('minecraft:smooth_quartz_stairs'))
.where('E', Predicates.blocks('minecraft:smooth_quartz_stairs'))
.where('F', Predicates.blocks('minecraft:smooth_quartz_stairs'))
.where('U', Predicates.blocks('minecraft:smooth_quartz_stairs'))
.where('X', Predicates.blocks('minecraft:smooth_quartz_stairs'))
.where('i', Predicates.blocks('minecraft:smooth_quartz_stairs'))
.where('T', Predicates.blocks('minecraft:smooth_quartz_stairs'))
.where('V', Predicates.blocks('minecraft:smooth_quartz_stairs'))
.where('I', Predicates.blocks('minecraft:smooth_quartz_stairs'))
.where('J', Predicates.blocks('minecraft:smooth_quartz_stairs'))
.where('f', Predicates.controller(Predicates.blocks(definition.get())))
.where('h',Predicates.blocks('naturesaura:offering_table'))
.where(' ', Predicates.any())
.where(']', Predicates.any())
.where('^', Predicates.any())
.build()
        )
.workableCasingModel(
            "minecraft:block/smooth_quartz",
            "minecraft:block/smooth_quartz"
        )
})

GTCEuStartupEvents.registry('gtceu:machine', event => {
    event.create('nether_Portal', 'multiblock')
        .rotationState(RotationState.NON_Y_AXIS)
        .recipeType('electric_furnace')
        .recipeModifiers(GTRecipeModifiers.ELECTRIC_OVERCLOCK.apply(OverclockingLogic.NON_PERFECT_OVERCLOCK))
        .pattern(definition => FactoryBlockPattern.start()
            // 多方块结构 - 所有字符串宽度 17，每层高度 34
            .aisle("      AAAAA      ", "      AAAAA      ", "      AAAAA      ", "                 ", "                 ", "                 ", "                 ", "                 ", "                 ", "                 ", "                 ", "                 ", "                 ", "                 ", "                 ", "                 ", "                 ", "                 ", "                 ", "                 ", "                 ", "                 ", "                 ", "                 ", "                 ", "                 ", "                 ", "                 ", "                 ", "                 ", "                 ", "                 ", "                 ", "                 ", "                 ")
            .aisle("    AAAAAAAAA    ", "    AABBBBBAA    ", "    AACCCCCAA    ", "      AAAAA      ", "                 ", "                 ", "                 ", "                 ", "                 ", "                 ", "                 ", "                 ", "                 ", "                 ", "                 ", "                 ", "                 ", "                 ", "                 ", "                 ", "                 ", "                 ", "                 ", "                 ", "                 ", "                 ", "                 ", "                 ", "                 ", "                 ", "                 ", "                 ", "                 ", "                 ", "                 ")
            .aisle("   AAAAAAAAAAA   ", "   ABBBBBBBBBA   ", "   ACCCCCCCCCA   ", "    AA     AA    ", "                 ", "                 ", "                 ", "                 ", "                 ", "                 ", "                 ", "                 ", "                 ", "                 ", "                 ", "                 ", "                 ", "                 ", "                 ", "                 ", "                 ", "        T        ", "       EFG       ", "       HFH       ", "       IFJ       ", "        M        ", "                 ", "                 ", "                 ", "                 ", "                 ", "                 ", "                 ", "                 ", "                 ")
            .aisle("  AAAAAAAAAAAAA  ", "  ABBBBBBBBBBBA  ", "  ACCCCCCCCCCCA  ", "   A         A   ", "                 ", "                 ", "                 ", "                 ", "                 ", "                 ", "                 ", "                 ", "                 ", "                 ", "                 ", "                 ", "                 ", "                 ", "                 ", "                 ", "                 ", "        T        ", "       LFL       ", "        M        ", "                 ", "                 ", "                 ", "                 ", "                 ", "                 ", "                 ", "                 ", "                 ", "                 ", "                 ")
            .aisle(" AAAAAAAAAAAAAAA ", " ABBBBBBBBBBBBBA ", " ACCCCCCCCCCCCCA ", "  A           A  ", "                 ", "                 ", "                 ", "                 ", "                 ", "                 ", "                 ", "                 ", "                 ", "                 ", "                 ", "                 ", "                 ", "                 ", "                 ", "                 ", "                 ", "        L        ", "       HFH       ", "        H        ", "                 ", "                 ", "                 ", "                 ", "                 ", "                 ", "                 ", "                 ", "                 ", "                 ", "                 ")
            .aisle(" AAAAAAAAAAAAAAA ", " ABBBBBBBBBBBBBA ", " ACCCCCCCCCCCCCA ", "  A           A  ", "                 ", "                 ", "                 ", "                 ", "                 ", "                 ", "                 ", "                 ", "                 ", "                 ", "                 ", "                 ", "                 ", "                 ", "                 ", "                 ", "       T T       ", "       K K       ", "       N N       ", "       N N       ", "       KLK       ", "       LFL       ", "        H        ", "                 ", "                 ", "                 ", "                 ", "                 ", "                 ", "                 ", "                 ")
            .aisle("AAAAAAAAAAAAAAAAA", "ABBBBBBBOBBBBBBBA", "ACCCCCCCOCCCCCCCA", " A     EOG     A ", "       IOJ       ", "       NON       ", "       IOJ       ", "       NON       ", "       IOJ       ", "       NON       ", "       IOJ       ", "       NON       ", "       IOJ       ", "       NON       ", "       IOJ       ", "       NON       ", "       IOJ       ", "       NON       ", "       EOG       ", "       POQ       ", "       FOR       ", "       ROF       ", "       ROR       ", "       KOK       ", "        K        ", "                 ", "                 ", "                 ", "                 ", "                 ", "                 ", "                 ", "                 ", "                 ", "                 ")
            .aisle("AAAAAAAAAAAAAAAAA", "ABBBBBBBOBBBBBBBA", "ACCCCCCCSCCCCCCCA", " A      S      A ", "        S        ", "        S        ", "        S        ", "        S        ", "        S        ", "        S        ", "        S        ", "        S        ", "        S        ", "        S        ", "        S        ", "        S        ", "        S        ", "        S        ", "        S        ", "       TST       ", "       DSD       ", "        S        ", "        S        ", "       TOT       ", "       KRK       ", "        R        ", "        R        ", "        N        ", "        N        ", "        N        ", "        N        ", "        N        ", "        U        ", "        K        ", "        M        ")
            .aisle("AAAAAAAAAAAAAAAAA", "VBBBBBBBOBBBBBBBA", "ACCCCCCCSCCCCCCCA", " A      S      A ", "        S        ", "        S        ", "        S        ", "        S        ", "        S        ", "        S        ", "        S        ", "        S        ", "        S        ", "        S        ", "        S        ", "        S        ", "        S        ", "        S        ", "        S        ", "        S        ", "       RSR       ", "       WSW       ", "       WSW       ", "       EOG       ", "       F F       ", "       R R       ", "       R R       ", "       IFJ       ", "       NFN       ", "       NFN       ", "       NFN       ", "       NFN       ", "       IFJ       ", "       XFY       ", "       Z/Z       ")
            .aisle("AAAAAAAAAAAAAAAAA", "ABBBBBBBOBBBBBBBA", "ACCCCCCCSCCCCCCCA", " A      S      A ", "        S        ", "        S        ", "        S        ", "        S        ", "        S        ", "        S        ", "        S        ", "        S        ", "        S        ", "        S        ", "        S        ", "        S        ", "        S        ", "        S        ", "        S        ", "       DSD       ", "       TST       ", "        S        ", "        S        ", "       DOD       ", "       MRM       ", "        R        ", "        R        ", "        N        ", "        N        ", "        N        ", "        N        ", "        N        ", "        U        ", "        T        ", "        M        ")
            .aisle("AAAAAAAAAAAAAAAAA", "ABBBBBBBOBBBBBBBA", "ACCCCCCCOCCCCCCCA", " A     EOG     A ", "       IOJ       ", "       NON       ", "       IOJ       ", "       NON       ", "       IOJ       ", "       NON       ", "       IOJ       ", "       NON       ", "       IOJ       ", "       NON       ", "       IOJ       ", "       NON       ", "       IOJ       ", "       NON       ", "       EOG       ", "       POQ       ", "       ROF       ", "       FOR       ", "       ROR       ", "       MOM       ", "        M        ", "                 ", "                 ", "                 ", "                 ", "                 ", "                 ", "                 ", "                 ", "                 ", "                 ")
            .aisle(" AAAAAAAAAAAAAAA ", " ABBBBBBBBBBBBBA ", " ACCCCCCCCCCCCCA ", "  A           A  ", "                 ", "                 ", "                 ", "                 ", "                 ", "                 ", "                 ", "                 ", "                 ", "                 ", "                 ", "                 ", "                 ", "                 ", "                 ", "                 ", "       D D       ", "       M M       ", "       N N       ", "       N N       ", "       MLM       ", "       LFL       ", "        H        ", "                 ", "                 ", "                 ", "                 ", "                 ", "                 ", "                 ", "                 ")
            .aisle(" AAAAAAAAAAAAAAA ", " ABBBBBBBBBBBBBA ", " ACCCCCCCCCCCCCA ", "  A           A  ", "                 ", "                 ", "                 ", "                 ", "                 ", "                 ", "                 ", "                 ", "                 ", "                 ", "                 ", "                 ", "                 ", "                 ", "                 ", "                 ", "                 ", "        L        ", "       HFH       ", "        H        ", "                 ", "                 ", "                 ", "                 ", "                 ", "                 ", "                 ", "                 ", "                 ", "                 ", "                 ")
            .aisle("  AAAAAAAAAAAAA  ", "  ABBBBBBBBBBBA  ", "  ACCCCCCCCCCCA  ", "   A         A   ", "                 ", "                 ", "                 ", "                 ", "                 ", "                 ", "                 ", "                 ", "                 ", "                 ", "                 ", "                 ", "                 ", "                 ", "                 ", "                 ", "                 ", "        D        ", "       LFL       ", "        K        ", "                 ", "                 ", "                 ", "                 ", "                 ", "                 ", "                 ", "                 ", "                 ", "                 ", "                 ")
            .aisle("   AAAAAAAAAAA   ", "   ABBBBBBBBBA   ", "   ACCCCCCCCCA   ", "    AA     AA    ", "                 ", "                 ", "                 ", "                 ", "                 ", "                 ", "                 ", "                 ", "                 ", "                 ", "                 ", "                 ", "                 ", "                 ", "                 ", "                 ", "                 ", "        D        ", "       EFG       ", "       HFH       ", "       IFJ       ", "        K        ", "                 ", "                 ", "                 ", "                 ", "                 ", "                 ", "                 ", "                 ", "                 ")
            .aisle("    AAAAAAAAA    ", "    AABBBBBAA    ", "    AACCCCCAA    ", "      AAAAA      ", "                 ", "                 ", "                 ", "                 ", "                 ", "                 ", "                 ", "                 ", "                 ", "                 ", "                 ", "                 ", "                 ", "                 ", "                 ", "                 ", "                 ", "                 ", "                 ", "                 ", "                 ", "                 ", "                 ", "                 ", "                 ", "                 ", "                 ", "                 ", "                 ", "                 ", "                 ")
            .aisle("      AAAAA      ", "      AAAAA      ", "      AAAAA      ", "                 ", "                 ", "                 ", "                 ", "                 ", "                 ", "                 ", "                 ", "                 ", "                 ", "                 ", "                 ", "                 ", "                 ", "                 ", "                 ", "                 ", "                 ", "                 ", "                 ", "                 ", "                 ", "                 ", "                 ", "                 ", "                 ", "                 ", "                 ", "                 ", "                 ", "                 ", "                 ")
            .where('V', Predicates.controller(Predicates.blocks(definition.get())))
            .where('B', Predicates.any())
            .where('O', Predicates.blocks('minecraft:obsidian'))
            .where('C', Predicates.blocks('connectedglass:clear_glass_magenta'))
            .where('E', Predicates.blocks('minecraft:blackstone_wall'))
            .where('G', Predicates.blocks('minecraft:blackstone_wall'))
            .where('I', Predicates.blocks('minecraft:blackstone_wall'))
            .where('J', Predicates.blocks('minecraft:blackstone_wall'))
            .where('N', Predicates.blocks('minecraft:chain'))
            .where('P', Predicates.blocks('minecraft:blackstone_wall'))
            .where('Q', Predicates.blocks('minecraft:blackstone_wall'))
            .where('T', Predicates.blocks('minecraft:blackstone_stairs'))
            .where('D', Predicates.blocks('minecraft:blackstone_stairs'))
            .where('F', Predicates.blocks('minecraft:gilded_blackstone'))
            .where('R', Predicates.blocks('minecraft:blackstone'))
            .where('/', Predicates.blocks('minecraft:lightning_rod'))
            .where(']', Predicates.blocks('minecraft:blackstone_wall'))
            .where('U', Predicates.blocks('minecraft:blackstone_wall'))
            .where('K', Predicates.blocks('minecraft:blackstone_stairs'))
            .where('M', Predicates.blocks('minecraft:blackstone_stairs'))
            .where('L', Predicates.blocks('minecraft:blackstone_slab'))
            .where('W', Predicates.blocks('minecraft:blackstone_wall'))
            .where('X', Predicates.blocks('minecraft:blackstone_stairs'))
            .where('Y', Predicates.blocks('minecraft:blackstone_stairs'))
            .where('Z', Predicates.blocks('minecraft:blackstone_stairs'))
            .where('S', Predicates.blocks('minecraft:nether_portal'))
            .where('H', Predicates.blocks('minecraft:blackstone_stairs'))
            .where(' ', Predicates.any())
            .where('A', Predicates.blocks('minecraft:polished_blackstone_bricks')
                .or(Predicates.autoAbilities(definition.getRecipeTypes())))
            .build()
        )
        .workableCasingModel(
            "minecraft:block/polished_blackstone_bricks",
            "minecraft:block/polished_blackstone_bricks"
        )
})

GTCEuStartupEvents.registry('gtceu:recipe_type', event => {
    event.create('the_bagua_of_heaven_and_earth')
        .category('the_bagua_of_heaven_and_earth')
        .setEUIO('in')
        .setMaxIOSize(1, 1, 0, 0)
        .setSlotOverlay(false, false, GuiTextures.SOLIDIFIER_OVERLAY)
        .setProgressBar(GuiTextures.PROGRESS_BAR_ARROW, FillDirection.LEFT_TO_RIGHT)
})

GTCEuStartupEvents.registry('gtceu:machine', event => {
    event.create('the_bagua_of_heaven_and_earth', 'multiblock')
        .rotationState(RotationState.NON_Y_AXIS)
        .recipeType('the_bagua_of_heaven_and_earth')
        .recipeModifiers(GTRecipeModifiers.ELECTRIC_OVERCLOCK.apply(OverclockingLogic.NON_PERFECT_OVERCLOCK))
        .pattern(definition => FactoryBlockPattern.start()
.aisle("                             BBBBBBBBBBBBBB                             ", "                             BBBBBBBBBBBBBB                             ", "                             BBBBBBBBBBBBBB                             ", "                             BBAAAAAAAAAABB                             ", "                             BBAAAAAAAAAABB                             ", "                             BBBBBBBBBBBBBB                             ", "                             BBBBBBBBBBBBBB                             ", "                             BBAAAAAAAAAABB                             ", "                             BBAAAAAAAAAABB                             ", "                             BBBBBBBBBBBBBB                             ", "                             BBBBBBBBBBBBBB                             ", "                             BBAAAABBAAAABB                             ", "                             BBAAAABBAAAABB                             ", "                             BBBBBBBBBBBBBB                             ", "                             BBBBBBBBBBBBBB                             ")
.aisle("                         BBBBBBBBBBBBBBBBBBBBBB                         ", "                         BBBBB             BBBB                         ", "                         BBBBB             BBBB                         ", "                         BBBBB             BBBB                         ", "                         BBBBB             BBBB                         ", "                         BBBBB             BBBB                         ", "                         BBBBB             BBBB                         ", "                         BBBBB             BBBB                         ", "                         BBBBB             BBBB                         ", "                         BBBBB             BBBB                         ", "                         BBBBB             BBBB                         ", "                         BBBBB             BBBB                         ", "                         BBBBB             BBBB                         ", "                         BBBBB             BBBB                         ", "                         BBBBB             BBBB                         ")
.aisle("                      BBBBBBBBBBBBBBBBBBBBBBBBBBBB                      ", "                      BBB                      BBB                      ", "                      BBB                      BBB                      ", "                      BBB                      BBB                      ", "                      BBB                      BBB                      ", "                      BBB                      BBB                      ", "                      BBB                      BBB                      ", "                      BBB                      BBB                      ", "                      BBB                      BBB                      ", "                      BBB                      BBB                      ", "                      BBB                      BBB                      ", "                      BBB                      BBB                      ", "                      BBB                      BBB                      ", "                      BBB                      BBB                      ", "                      BBB                      BBB                      ")
.aisle("                    BBBBBBBBBBBBBBBBBBBBBBBBBBBBBBBB                    ", "                    BB                            BB                    ", "                    BB                            BB                    ", "                    BB                            BB                    ", "                    BB                            BB                    ", "                    BB                            BB                    ", "                    BB                            BB                    ", "                    BB                            BB                    ", "                    BB                            BB                    ", "                    BB                            BB                    ", "                    BB                            BB                    ", "                    BB                            BB                    ", "                    BB                            BB                    ", "                    BB                            BB                    ", "                    BB                            BB                    ")
.aisle("                  BBBBBBBBBBBBBBBBBBBBBBBBBBBBBBBBBBBB                  ", "                  BB                                BB                  ", "                  BB                                BB                  ", "                  BB                                BB                  ", "                  BB                                BB                  ", "                  BB                                BB                  ", "                  BB                                BB                  ", "                  BB                                BB                  ", "                  BB                                BB                  ", "                  BB                                BB                  ", "                  BB                                BB                  ", "                  BB                                BB                  ", "                  BB                                BB                  ", "                  BB                                BB                  ", "                  BB                                BB                  ")
.aisle("                 BBBBBBBBBBBBBBBBBBBBBBBBBBBBBBBBBBBBBB                 ", "                 B                                    B                 ", "                 B                                    B                 ", "                 B                                    B                 ", "                 B                                    B                 ", "                 B                                    B                 ", "                 B                                    B                 ", "                 B                                    B                 ", "                 B                                    B                 ", "                 B                                    B                 ", "                 B                                    B                 ", "                 B                                    B                 ", "                 B                                    B                 ", "                 B                                    B                 ", "                 B                                    B                 ")
.aisle("               BBBBBBBBBBBBBBBBBBBBBBBBBBBBBBBBBBBBBBBBBB               ", "               BB                                      BB               ", "               BB                                      BB               ", "               BB                                      BB               ", "               BB                                      BB               ", "               BB                                      BB               ", "               BB                                      BB               ", "               BB                                      BB               ", "               BB                                      BB               ", "               BB                                      BB               ", "               BB                                      BB               ", "               BB                                      BB               ", "               BB                                      BB               ", "               BB                                      BB               ", "               BB                                      BB               ")
.aisle("              BBBBBBBBBBBBBBBBBBBBBBBBBBBBBBBBBBBBBBBBBBBB              ", "              B                                          B              ", "              B                                          B              ", "              A                                          A              ", "              A                                          A              ", "              B                                          B              ", "              B                                          B              ", "              A                                          A              ", "              A                                          A              ", "              B                                          B              ", "              B                                          B              ", "              A                                          A              ", "              A                                          A              ", "              B                                          B              ", "              B                                          B              ")
.aisle("            BBBBBBBBBBBBBBBBBBBBBBBBBBBBBBBBBBBBBBBBBBBBBBBB            ", "            BB                                            BB            ", "            BB                                            BB            ", "            AA                                            AA            ", "            AA                                            AA            ", "            BB                                            BB            ", "            BB                                            BB            ", "            AA                                            AA            ", "            AA                                            AA            ", "            BB                                            BB            ", "            BB                                            BB            ", "            AA                                            AA            ", "            AA                                            AA            ", "            BB                                            BB            ", "            BB                                            BB            ")
.aisle("           BBBBBBBBBBBBBBBBBBBBBBBBBBBBBBBBBBBBBBBBBBBBBBBBBB           ", "           B                                                B           ", "           B                                                B           ", "           A                                                A           ", "           A                                                A           ", "           B                                                B           ", "           B                                                B           ", "           A                                                A           ", "           A                                                A           ", "           B                                                B           ", "           B                                                B           ", "           A                                                A           ", "           A                                                A           ", "           B                                                B           ", "           B                                                B           ")
.aisle("          BBBBBBBBBBBBBBBBBBBBBBBBBBBBBBBBBBBBBBBBBBBBBBBBBBBB          ", "          B                                                  B          ", "          B                                                  B          ", "          A                                                  B          ", "          A                                                  B          ", "          B                                                  B          ", "          B                                                  B          ", "          A                                                  B          ", "          A                                                  B          ", "          B                                                  B          ", "          B                                                  B          ", "          A                                                  B          ", "          A                                                  B          ", "          B                                                  B          ", "          B                                                  B          ")
.aisle("         BBBBBBBBBBBBBBBBBBBBBBBBBBBBBBBBBBBBBBBBBBBBBBBBBBBBBB         ", "         B                                                    B         ", "         B                                                    B         ", "         A                                                    A         ", "         A                                                    A         ", "         B                                                    B         ", "         B                                                    B         ", "         A                                                    A         ", "         A                                                    A         ", "         B                                                    B         ", "         B                                                    B         ", "         A                                                    A         ", "         A                                                    A         ", "         B                                                    B         ", "         B                                                    B         ")
.aisle("        BBBBBBBBBBBBBBBBBBBBBBBBBBBBBBBBBBBBBBBBBBBBBBBBBBBBBBBB        ", "        B                                                      B        ", "        B                                                      B        ", "        A                                                      A        ", "        A                                                      A        ", "        B                                                      B        ", "        B                                                      B        ", "        A                                                      A        ", "        A                                                      A        ", "        B                                                      B        ", "        B                                                      B        ", "        A                                                      A        ", "        A                                                      A        ", "        B                                                      B        ", "        B                                                      B        ")
.aisle("        BBBBBBBBBBBBBBBBBBBBBBBBBBBBBBBBBBBBBBBBBBBBBBBBBBBBBBBB        ", "        B                                                      B        ", "        B                                                      B        ", "        A                                                      A        ", "        A                                                      A        ", "        B                                                      B        ", "        B                                                      B        ", "        A                                                      A        ", "        A                                                      A        ", "        B                                                      B        ", "        B                                                      B        ", "        A                                                      A        ", "        A                                                      A        ", "        B                                                      B        ", "        B                                                      B        ")
.aisle("       BBBBBBBBBBBBBBBBBBBBBBBBBBBBBBBBBBBBBBBBBBBBBBBBBBBBBBBBBB       ", "       B                                                        B       ", "       B                                                        B       ", "       A                                                        A       ", "       A                                                        A       ", "       B                                                        B       ", "       B                                                        B       ", "       A                                                        A       ", "       A                                                        A       ", "       B                                                        B       ", "       B                                                        B       ", "       A                                                        A       ", "       A                                                        A       ", "       B                                                        B       ", "       B                                                        B       ")
.aisle("      BBBBBBBBBBBBBBBBBBBBBBBBBBBBBBBBBBBBBBBBBBBBBBBBBBBBBBBBBBBB      ", "      B                                                          B      ", "      B                                                          B      ", "      B                                                          B      ", "      B                                                          B      ", "      B                                                          B      ", "      B                                                          B      ", "      B                                                          B      ", "      B                                                          B      ", "      B                                                          B      ", "      B                                                          B      ", "      B                                                          B      ", "      B                                                          B      ", "      B                                                          B      ", "      B                                                          B      ")
.aisle("      BBBBBBBBBBBBBBBBBBBBBBBBBBBBBBBBBBBBBBBBBBBBBAAAAAABBBBBBBBB      ", "      B                                                          B      ", "      B                                                          B      ", "      B                                                          B      ", "      B                                                          B      ", "      B                                                          B      ", "      B                                                          B      ", "      B                                                          B      ", "      B                                                          B      ", "      B                                                          B      ", "      B                                                          B      ", "      B                                                          B      ", "      B                                                          B      ", "      B                                                          B      ", "      B                                                          B      ")
.aisle("     BBBBBBBBBBBBBBBBBBBBBBBBBBBBBBBBBBBBBBBBBBBAAAAAAAAAAAABBBBBBB     ", "     B                                                            B     ", "     B                                                            B     ", "     B                                                            B     ", "     B                                                            B     ", "     B                                                            B     ", "     B                                                            B     ", "     B                                                            B     ", "     B                                                            B     ", "     B                                                            B     ", "     B                                                            B     ", "     B                                                            B     ", "     B                                                            B     ", "     B                                                            B     ", "     B                                                            B     ")
.aisle("    BBBBBBBBBBBBBBBBBBBBBBBBBBBBBBBBBBBBBBBBBBBAAAAAAAAAAAAAABBBBBBB    ", "    B                                                              B    ", "    B                                                              B    ", "    B                                                              B    ", "    B                                                              B    ", "    B                                                              B    ", "    B                                                              B    ", "    B                                                              B    ", "    B                                                              B    ", "    B                                                              B    ", "    B                                                              B    ", "    B                                                              B    ", "    B                                                              B    ", "    B                                                              B    ", "    B                                                              B    ")
.aisle("    BBBBBBBBBBBBBBBBBBBBBBBBBBBBBBBBBBBBBBBBBAAAAAAAAAAAAAAAAAABBBBB    ", "    B                                                              B    ", "    B                                                              B    ", "    B                                                              B    ", "    B                                                              B    ", "    B                                                              B    ", "    B                                                              B    ", "    B                                                              B    ", "    B                                                              B    ", "    B                                                              B    ", "    B                                                              B    ", "    B                                                              B    ", "    B                                                              B    ", "    B                                                              B    ", "    B                                                              B    ")
.aisle("   BBBBBBBBBBBBBBBBBBBBBBBBBBBBBBBBBBBBBBBBAAAAAAAAAAAAAAAAAAAAAABBBB   ", "   B                                                                B   ", "   B                                                                B   ", "   B                                                                B   ", "   B                                                                B   ", "   B                                                                B   ", "   B                                                                B   ", "   B                                                                B   ", "   B                                                                B   ", "   B                                                                B   ", "   B                                                                B   ", "   B                                                                B   ", "   B                                                                B   ", "   B                                                                B   ", "   B                                                                B   ")
.aisle("   BBBBBBBBBBBBBBBBBBBBBBBBBBBBBBBBBBBBBBBAAAAAAAAAAAAAAAAAAAAAAAABBB   ", "   B                                                                B   ", "   B                                                                B   ", "   B                                                                B   ", "   B                                                                B   ", "   B                                                                B   ", "   B                                                                B   ", "   B                                                                B   ", "   B                                                                B   ", "   B                                                                B   ", "   B                                                                B   ", "   B                                                                B   ", "   B                                                                B   ", "   B                                                                B   ", "   B                                                                B   ")
.aisle("  BBBBBBBBBBBBBBBBBBBBBBBBBBBBBBBBBBBBBBBAAAAAAAAAAAAAAAAAAAAAAAAAABBB  ", "  B                                                                  B  ", "  B                                                                  B  ", "  B                                                                  B  ", "  B                                                                  B  ", "  B                                                                  B  ", "  B                                                                  B  ", "  B                                                                  B  ", "  B                                                                  B  ", "  B                                                                  B  ", "  B                                                                  B  ", "  B                                                                  B  ", "  B                                                                  B  ", "  B                                                                  B  ", "  B                                                                  B  ")
.aisle("  BBBBBBBBBBBBBBBBBBBBBBBBBBBBBBBBBBBBBBAAAAAAAAAAAAAAAAAAAAAAAAAAAABB  ", "  B                                                                  B  ", "  B                                                                  B  ", "  B                                                                  B  ", "  B                                                                  B  ", "  B                                                                  B  ", "  B                                                                  B  ", "  B                                                                  B  ", "  B                                                                  B  ", "  B                                                                  B  ", "  B                                                                  B  ", "  B                                                                  B  ", "  B                                                                  B  ", "  B                                                                  B  ", "  B                                                                  B  ")
.aisle("  BBBBBBBBBBBBBBBBBBBBBBBBBBBBBBBBBBBBBBAAAAAAAAAAAAAAAAAAAAAAAAAAAABB  ", "  B                                                                  B  ", "  B                                                                  B  ", "  B                                                                  B  ", "  B                                                                  B  ", "  B                                                                  B  ", "  B                                                                  B  ", "  B                                                                  B  ", "  B                                                                  B  ", "  B                                                                  B  ", "  B                                                                  B  ", "  B                                                                  B  ", "  B                                                                  B  ", "  B                                                                  B  ", "  B                                                                  B  ")
